2018-10-03 07:23:18,242 - flask.app - ERROR - Exception on /users/ [POST]
Traceback (most recent call last):
  File "/Users/apple/.local/share/virtualenvs/flask_structure-RpFDbM_9/lib/python3.6/site-packages/sqlalchemy/engine/base.py", line 1193, in _execute_context
    context)
  File "/Users/apple/.local/share/virtualenvs/flask_structure-RpFDbM_9/lib/python3.6/site-packages/sqlalchemy/engine/default.py", line 509, in do_execute
    cursor.execute(statement, parameters)
sqlite3.IntegrityError: UNIQUE constraint failed: users.username

The above exception was the direct cause of the following exception:

Traceback (most recent call last):
  File "/Users/apple/.local/share/virtualenvs/flask_structure-RpFDbM_9/lib/python3.6/site-packages/flask/app.py", line 2292, in wsgi_app
    response = self.full_dispatch_request()
  File "/Users/apple/.local/share/virtualenvs/flask_structure-RpFDbM_9/lib/python3.6/site-packages/flask/app.py", line 1815, in full_dispatch_request
    rv = self.handle_user_exception(e)
  File "/Users/apple/.local/share/virtualenvs/flask_structure-RpFDbM_9/lib/python3.6/site-packages/flask/app.py", line 1718, in handle_user_exception
    reraise(exc_type, exc_value, tb)
  File "/Users/apple/.local/share/virtualenvs/flask_structure-RpFDbM_9/lib/python3.6/site-packages/flask/_compat.py", line 35, in reraise
    raise value
  File "/Users/apple/.local/share/virtualenvs/flask_structure-RpFDbM_9/lib/python3.6/site-packages/flask/app.py", line 1813, in full_dispatch_request
    rv = self.dispatch_request()
  File "/Users/apple/.local/share/virtualenvs/flask_structure-RpFDbM_9/lib/python3.6/site-packages/flask/app.py", line 1799, in dispatch_request
    return self.view_functions[rule.endpoint](**req.view_args)
  File "/Users/apple/premanuj/flaskapps/flask_structure/app/users/__init__.py", line 13, in user
    help(ma)
  File "/Users/apple/premanuj/flaskapps/flask_structure/app/users/service.py", line 6, in new_user
    result = user.save(data)
  File "/Users/apple/premanuj/flaskapps/flask_structure/app/users/models.py", line 51, in save
    db.session.commit()
  File "/Users/apple/.local/share/virtualenvs/flask_structure-RpFDbM_9/lib/python3.6/site-packages/sqlalchemy/orm/scoping.py", line 153, in do
    return getattr(self.registry(), name)(*args, **kwargs)
  File "/Users/apple/.local/share/virtualenvs/flask_structure-RpFDbM_9/lib/python3.6/site-packages/sqlalchemy/orm/session.py", line 943, in commit
    self.transaction.commit()
  File "/Users/apple/.local/share/virtualenvs/flask_structure-RpFDbM_9/lib/python3.6/site-packages/sqlalchemy/orm/session.py", line 467, in commit
    self._prepare_impl()
  File "/Users/apple/.local/share/virtualenvs/flask_structure-RpFDbM_9/lib/python3.6/site-packages/sqlalchemy/orm/session.py", line 447, in _prepare_impl
    self.session.flush()
  File "/Users/apple/.local/share/virtualenvs/flask_structure-RpFDbM_9/lib/python3.6/site-packages/sqlalchemy/orm/session.py", line 2254, in flush
    self._flush(objects)
  File "/Users/apple/.local/share/virtualenvs/flask_structure-RpFDbM_9/lib/python3.6/site-packages/sqlalchemy/orm/session.py", line 2380, in _flush
    transaction.rollback(_capture_exception=True)
  File "/Users/apple/.local/share/virtualenvs/flask_structure-RpFDbM_9/lib/python3.6/site-packages/sqlalchemy/util/langhelpers.py", line 66, in __exit__
    compat.reraise(exc_type, exc_value, exc_tb)
  File "/Users/apple/.local/share/virtualenvs/flask_structure-RpFDbM_9/lib/python3.6/site-packages/sqlalchemy/util/compat.py", line 249, in reraise
    raise value
  File "/Users/apple/.local/share/virtualenvs/flask_structure-RpFDbM_9/lib/python3.6/site-packages/sqlalchemy/orm/session.py", line 2344, in _flush
    flush_context.execute()
  File "/Users/apple/.local/share/virtualenvs/flask_structure-RpFDbM_9/lib/python3.6/site-packages/sqlalchemy/orm/unitofwork.py", line 391, in execute
    rec.execute(self)
  File "/Users/apple/.local/share/virtualenvs/flask_structure-RpFDbM_9/lib/python3.6/site-packages/sqlalchemy/orm/unitofwork.py", line 556, in execute
    uow
  File "/Users/apple/.local/share/virtualenvs/flask_structure-RpFDbM_9/lib/python3.6/site-packages/sqlalchemy/orm/persistence.py", line 181, in save_obj
    mapper, table, insert)
  File "/Users/apple/.local/share/virtualenvs/flask_structure-RpFDbM_9/lib/python3.6/site-packages/sqlalchemy/orm/persistence.py", line 866, in _emit_insert_statements
    execute(statement, params)
  File "/Users/apple/.local/share/virtualenvs/flask_structure-RpFDbM_9/lib/python3.6/site-packages/sqlalchemy/engine/base.py", line 948, in execute
    return meth(self, multiparams, params)
  File "/Users/apple/.local/share/virtualenvs/flask_structure-RpFDbM_9/lib/python3.6/site-packages/sqlalchemy/sql/elements.py", line 269, in _execute_on_connection
    return connection._execute_clauseelement(self, multiparams, params)
  File "/Users/apple/.local/share/virtualenvs/flask_structure-RpFDbM_9/lib/python3.6/site-packages/sqlalchemy/engine/base.py", line 1060, in _execute_clauseelement
    compiled_sql, distilled_params
  File "/Users/apple/.local/share/virtualenvs/flask_structure-RpFDbM_9/lib/python3.6/site-packages/sqlalchemy/engine/base.py", line 1200, in _execute_context
    context)
  File "/Users/apple/.local/share/virtualenvs/flask_structure-RpFDbM_9/lib/python3.6/site-packages/sqlalchemy/engine/base.py", line 1413, in _handle_dbapi_exception
    exc_info
  File "/Users/apple/.local/share/virtualenvs/flask_structure-RpFDbM_9/lib/python3.6/site-packages/sqlalchemy/util/compat.py", line 265, in raise_from_cause
    reraise(type(exception), exception, tb=exc_tb, cause=cause)
  File "/Users/apple/.local/share/virtualenvs/flask_structure-RpFDbM_9/lib/python3.6/site-packages/sqlalchemy/util/compat.py", line 248, in reraise
    raise value.with_traceback(tb)
  File "/Users/apple/.local/share/virtualenvs/flask_structure-RpFDbM_9/lib/python3.6/site-packages/sqlalchemy/engine/base.py", line 1193, in _execute_context
    context)
  File "/Users/apple/.local/share/virtualenvs/flask_structure-RpFDbM_9/lib/python3.6/site-packages/sqlalchemy/engine/default.py", line 509, in do_execute
    cursor.execute(statement, parameters)
sqlalchemy.exc.IntegrityError: (sqlite3.IntegrityError) UNIQUE constraint failed: users.username [SQL: 'INSERT INTO users (username, password_hash, email_address, user_type) VALUES (?, ?, ?, ?)'] [parameters: ('premanuja', None, 'mesubedianuj@gmail.com', None)] (Background on this error at: http://sqlalche.me/e/gkpj)
