2018-09-21 08:30:55,999 - flask.app - ERROR - Exception on /users/ [GET]
Traceback (most recent call last):
  File "/Users/apple/.local/share/virtualenvs/flask_structure-RpFDbM_9/lib/python3.6/site-packages/flask/app.py", line 2292, in wsgi_app
    response = self.full_dispatch_request()
  File "/Users/apple/.local/share/virtualenvs/flask_structure-RpFDbM_9/lib/python3.6/site-packages/flask/app.py", line 1815, in full_dispatch_request
    rv = self.handle_user_exception(e)
  File "/Users/apple/.local/share/virtualenvs/flask_structure-RpFDbM_9/lib/python3.6/site-packages/flask/app.py", line 1718, in handle_user_exception
    reraise(exc_type, exc_value, tb)
  File "/Users/apple/.local/share/virtualenvs/flask_structure-RpFDbM_9/lib/python3.6/site-packages/flask/_compat.py", line 35, in reraise
    raise value
  File "/Users/apple/.local/share/virtualenvs/flask_structure-RpFDbM_9/lib/python3.6/site-packages/flask/app.py", line 1813, in full_dispatch_request
    rv = self.dispatch_request()
  File "/Users/apple/.local/share/virtualenvs/flask_structure-RpFDbM_9/lib/python3.6/site-packages/flask/app.py", line 1799, in dispatch_request
    return self.view_functions[rule.endpoint](**req.view_args)
  File "/Users/apple/premanuj/flaskapps/flask_structure/app/users/__init__.py", line 8, in user
    def user():
ZeroDivisionError: division by zero
2018-09-21 08:32:16,095 - flask.app - ERROR - Exception on /users/ [GET]
Traceback (most recent call last):
  File "/Users/apple/.local/share/virtualenvs/flask_structure-RpFDbM_9/lib/python3.6/site-packages/flask/app.py", line 2292, in wsgi_app
    response = self.full_dispatch_request()
  File "/Users/apple/.local/share/virtualenvs/flask_structure-RpFDbM_9/lib/python3.6/site-packages/flask/app.py", line 1815, in full_dispatch_request
    rv = self.handle_user_exception(e)
  File "/Users/apple/.local/share/virtualenvs/flask_structure-RpFDbM_9/lib/python3.6/site-packages/flask/app.py", line 1718, in handle_user_exception
    reraise(exc_type, exc_value, tb)
  File "/Users/apple/.local/share/virtualenvs/flask_structure-RpFDbM_9/lib/python3.6/site-packages/flask/_compat.py", line 35, in reraise
    raise value
  File "/Users/apple/.local/share/virtualenvs/flask_structure-RpFDbM_9/lib/python3.6/site-packages/flask/app.py", line 1813, in full_dispatch_request
    rv = self.dispatch_request()
  File "/Users/apple/.local/share/virtualenvs/flask_structure-RpFDbM_9/lib/python3.6/site-packages/flask/app.py", line 1799, in dispatch_request
    return self.view_functions[rule.endpoint](**req.view_args)
  File "/Users/apple/premanuj/flaskapps/flask_structure/app/users/__init__.py", line 8, in user
    def user():
ZeroDivisionError: division by zero
2018-09-21 08:32:43,061 - flask.app - ERROR - Exception on /users/ [GET]
Traceback (most recent call last):
  File "/Users/apple/.local/share/virtualenvs/flask_structure-RpFDbM_9/lib/python3.6/site-packages/flask/app.py", line 2292, in wsgi_app
    response = self.full_dispatch_request()
  File "/Users/apple/.local/share/virtualenvs/flask_structure-RpFDbM_9/lib/python3.6/site-packages/flask/app.py", line 1815, in full_dispatch_request
    rv = self.handle_user_exception(e)
  File "/Users/apple/.local/share/virtualenvs/flask_structure-RpFDbM_9/lib/python3.6/site-packages/flask/app.py", line 1718, in handle_user_exception
    reraise(exc_type, exc_value, tb)
  File "/Users/apple/.local/share/virtualenvs/flask_structure-RpFDbM_9/lib/python3.6/site-packages/flask/_compat.py", line 35, in reraise
    raise value
  File "/Users/apple/.local/share/virtualenvs/flask_structure-RpFDbM_9/lib/python3.6/site-packages/flask/app.py", line 1813, in full_dispatch_request
    rv = self.dispatch_request()
  File "/Users/apple/.local/share/virtualenvs/flask_structure-RpFDbM_9/lib/python3.6/site-packages/flask/app.py", line 1799, in dispatch_request
    return self.view_functions[rule.endpoint](**req.view_args)
  File "/Users/apple/premanuj/flaskapps/flask_structure/app/users/__init__.py", line 8, in user
    def user():
ZeroDivisionError: division by zero
2018-09-21 08:39:04,021 - flask.app - ERROR - {'name': 'anuj'}
2018-09-21 08:39:04,040 - flask.app - ERROR - Exception on /users/ [GET]
Traceback (most recent call last):
  File "/Users/apple/.local/share/virtualenvs/flask_structure-RpFDbM_9/lib/python3.6/site-packages/flask/app.py", line 1974, in make_response
    rv = self.response_class.force_type(rv, request.environ)
  File "/Users/apple/.local/share/virtualenvs/flask_structure-RpFDbM_9/lib/python3.6/site-packages/werkzeug/wrappers.py", line 921, in force_type
    response = BaseResponse(*_run_wsgi_app(response, environ))
  File "/Users/apple/.local/share/virtualenvs/flask_structure-RpFDbM_9/lib/python3.6/site-packages/werkzeug/wrappers.py", line 59, in _run_wsgi_app
    return _run_wsgi_app(*args)
  File "/Users/apple/.local/share/virtualenvs/flask_structure-RpFDbM_9/lib/python3.6/site-packages/werkzeug/test.py", line 923, in run_wsgi_app
    app_rv = app(environ, start_response)
TypeError: 'dict' object is not callable

During handling of the above exception, another exception occurred:

Traceback (most recent call last):
  File "/Users/apple/.local/share/virtualenvs/flask_structure-RpFDbM_9/lib/python3.6/site-packages/flask/app.py", line 2292, in wsgi_app
    response = self.full_dispatch_request()
  File "/Users/apple/.local/share/virtualenvs/flask_structure-RpFDbM_9/lib/python3.6/site-packages/flask/app.py", line 1816, in full_dispatch_request
    return self.finalize_request(rv)
  File "/Users/apple/.local/share/virtualenvs/flask_structure-RpFDbM_9/lib/python3.6/site-packages/flask/app.py", line 1831, in finalize_request
    response = self.make_response(rv)
  File "/Users/apple/.local/share/virtualenvs/flask_structure-RpFDbM_9/lib/python3.6/site-packages/flask/app.py", line 1982, in make_response
    reraise(TypeError, new_error, sys.exc_info()[2])
  File "/Users/apple/.local/share/virtualenvs/flask_structure-RpFDbM_9/lib/python3.6/site-packages/flask/_compat.py", line 34, in reraise
    raise value.with_traceback(tb)
  File "/Users/apple/.local/share/virtualenvs/flask_structure-RpFDbM_9/lib/python3.6/site-packages/flask/app.py", line 1974, in make_response
    rv = self.response_class.force_type(rv, request.environ)
  File "/Users/apple/.local/share/virtualenvs/flask_structure-RpFDbM_9/lib/python3.6/site-packages/werkzeug/wrappers.py", line 921, in force_type
    response = BaseResponse(*_run_wsgi_app(response, environ))
  File "/Users/apple/.local/share/virtualenvs/flask_structure-RpFDbM_9/lib/python3.6/site-packages/werkzeug/wrappers.py", line 59, in _run_wsgi_app
    return _run_wsgi_app(*args)
  File "/Users/apple/.local/share/virtualenvs/flask_structure-RpFDbM_9/lib/python3.6/site-packages/werkzeug/test.py", line 923, in run_wsgi_app
    app_rv = app(environ, start_response)
TypeError: 'dict' object is not callable
The view function did not return a valid response. The return type must be a string, tuple, Response instance, or WSGI callable, but it was a dict.
2018-09-21 08:41:03,077 - flask.app - ERROR - {'name': 'anuj'}
2018-09-21 08:41:03,077 - flask.app - ERROR - Exception on /users/ [GET]
Traceback (most recent call last):
  File "/Users/apple/.local/share/virtualenvs/flask_structure-RpFDbM_9/lib/python3.6/site-packages/flask/app.py", line 1974, in make_response
    rv = self.response_class.force_type(rv, request.environ)
  File "/Users/apple/.local/share/virtualenvs/flask_structure-RpFDbM_9/lib/python3.6/site-packages/werkzeug/wrappers.py", line 921, in force_type
    response = BaseResponse(*_run_wsgi_app(response, environ))
  File "/Users/apple/.local/share/virtualenvs/flask_structure-RpFDbM_9/lib/python3.6/site-packages/werkzeug/test.py", line 923, in run_wsgi_app
    app_rv = app(environ, start_response)
TypeError: 'dict' object is not callable

During handling of the above exception, another exception occurred:

Traceback (most recent call last):
  File "/Users/apple/.local/share/virtualenvs/flask_structure-RpFDbM_9/lib/python3.6/site-packages/flask/app.py", line 2292, in wsgi_app
    response = self.full_dispatch_request()
  File "/Users/apple/.local/share/virtualenvs/flask_structure-RpFDbM_9/lib/python3.6/site-packages/flask/app.py", line 1816, in full_dispatch_request
    return self.finalize_request(rv)
  File "/Users/apple/.local/share/virtualenvs/flask_structure-RpFDbM_9/lib/python3.6/site-packages/flask/app.py", line 1831, in finalize_request
    response = self.make_response(rv)
  File "/Users/apple/.local/share/virtualenvs/flask_structure-RpFDbM_9/lib/python3.6/site-packages/flask/app.py", line 1982, in make_response
    reraise(TypeError, new_error, sys.exc_info()[2])
  File "/Users/apple/.local/share/virtualenvs/flask_structure-RpFDbM_9/lib/python3.6/site-packages/flask/_compat.py", line 34, in reraise
    raise value.with_traceback(tb)
  File "/Users/apple/.local/share/virtualenvs/flask_structure-RpFDbM_9/lib/python3.6/site-packages/flask/app.py", line 1974, in make_response
    rv = self.response_class.force_type(rv, request.environ)
  File "/Users/apple/.local/share/virtualenvs/flask_structure-RpFDbM_9/lib/python3.6/site-packages/werkzeug/wrappers.py", line 921, in force_type
    response = BaseResponse(*_run_wsgi_app(response, environ))
  File "/Users/apple/.local/share/virtualenvs/flask_structure-RpFDbM_9/lib/python3.6/site-packages/werkzeug/test.py", line 923, in run_wsgi_app
    app_rv = app(environ, start_response)
TypeError: 'dict' object is not callable
The view function did not return a valid response. The return type must be a string, tuple, Response instance, or WSGI callable, but it was a dict.
2018-09-21 08:41:30,822 - flask.app - ERROR - {'name': 'anuj'}
2018-09-21 08:41:30,822 - flask.app - ERROR - Exception on /users/ [GET]
Traceback (most recent call last):
  File "/Users/apple/.local/share/virtualenvs/flask_structure-RpFDbM_9/lib/python3.6/site-packages/flask/app.py", line 1974, in make_response
    rv = self.response_class.force_type(rv, request.environ)
  File "/Users/apple/.local/share/virtualenvs/flask_structure-RpFDbM_9/lib/python3.6/site-packages/werkzeug/wrappers.py", line 921, in force_type
    response = BaseResponse(*_run_wsgi_app(response, environ))
  File "/Users/apple/.local/share/virtualenvs/flask_structure-RpFDbM_9/lib/python3.6/site-packages/werkzeug/test.py", line 923, in run_wsgi_app
    app_rv = app(environ, start_response)
TypeError: 'dict' object is not callable

During handling of the above exception, another exception occurred:

Traceback (most recent call last):
  File "/Users/apple/.local/share/virtualenvs/flask_structure-RpFDbM_9/lib/python3.6/site-packages/flask/app.py", line 2292, in wsgi_app
    response = self.full_dispatch_request()
  File "/Users/apple/.local/share/virtualenvs/flask_structure-RpFDbM_9/lib/python3.6/site-packages/flask/app.py", line 1816, in full_dispatch_request
    return self.finalize_request(rv)
  File "/Users/apple/.local/share/virtualenvs/flask_structure-RpFDbM_9/lib/python3.6/site-packages/flask/app.py", line 1831, in finalize_request
    response = self.make_response(rv)
  File "/Users/apple/.local/share/virtualenvs/flask_structure-RpFDbM_9/lib/python3.6/site-packages/flask/app.py", line 1982, in make_response
    reraise(TypeError, new_error, sys.exc_info()[2])
  File "/Users/apple/.local/share/virtualenvs/flask_structure-RpFDbM_9/lib/python3.6/site-packages/flask/_compat.py", line 34, in reraise
    raise value.with_traceback(tb)
  File "/Users/apple/.local/share/virtualenvs/flask_structure-RpFDbM_9/lib/python3.6/site-packages/flask/app.py", line 1974, in make_response
    rv = self.response_class.force_type(rv, request.environ)
  File "/Users/apple/.local/share/virtualenvs/flask_structure-RpFDbM_9/lib/python3.6/site-packages/werkzeug/wrappers.py", line 921, in force_type
    response = BaseResponse(*_run_wsgi_app(response, environ))
  File "/Users/apple/.local/share/virtualenvs/flask_structure-RpFDbM_9/lib/python3.6/site-packages/werkzeug/test.py", line 923, in run_wsgi_app
    app_rv = app(environ, start_response)
TypeError: 'dict' object is not callable
The view function did not return a valid response. The return type must be a string, tuple, Response instance, or WSGI callable, but it was a dict.
